Workbook

Sheet Project Plan 
B2: Milestone | C2: Work Package | D2: Objective | E2: Activities | G2: Deliverables | H2: Format of Deliverable | I2: Timeframe | L2: Year 1 Budget incl. VAT | P2: TOTAL
E3: No. | F3: Details | I3: Start (Month) | J3: End (Month) | K3: Duration | L3: Quarter 1 | M3: Quarter 2 | N3: Quarter 3 | O3: Quarter 4
B4: 1. Initiation | C4: 1.1. Project Legal & Administration | D4: To ensure project management and legal & administration requirements are in place for the successful implementation of the project | E4: 1.1.1 | F4: Understand project objectives, scope, and deliverables. | G4: Completed project proposal | H4: PDF | I4: Month 1 | J4: Month 1 | K4: 1 Month | L4: 0 | M4: 0 | N4: 0 | O4: 0 | P4: =SUM(L4:O4)
E5: 1.1.2 | F5: Ensure all project related contracts are in place for the project | G5: Signed Contracts
B6: Sub-Total 1 | L6: =SUM(L4) | M6: =SUM(M4) -> 0 | N6: =SUM(N4) -> 0 | O6: =SUM(O4) -> 0 | P6: =SUM(P4) -> 0
B7: 2. Planning | C7: 2.1 Project Planning | D7: Establish a clear, legally binding framework for the project, ensuring collaboration and understanding between all parties. | E7: 2.2.1 | F7: Develop Project Execution Plan in consultation with TIA Specialits | G7: Project Execution Document | H7: PDF | I7: Month 1 | J7: Month 1 | K7: 1 Month | L7: 0 | M7: 0 | N7: 0 | O7: 0 | P7: =SUM(L7:O7)
E8: 2.2.2 | F8: Host Project kick off meeting to ensure all relevant stakholders understand how the project will be implemented
C9: 2.2. Business Sustainability Model | D9: To build a business sustainability model that aims to reduce dependence on government support for the technology in the future. | E9: 2.2.3 | F9: Develop a stakholder map to identifiy funding sources and potential partners for Umhlatuze | G9: Stakeholder map including funding sources | I9: Month 1 | J9: Month 2 | K9: 12 Months | L9: 0 | M9: 20000 | N9: 20000 | O9: 10000 | P9: =SUM(L9:O9)
E10: 2.2.4 | F10: Develop a business sustainability model for Sisanda App Universe | G10: Business sustainability model | I10: Month 3 | J10: Month 9
E11: 2.2.5 | F11: Source funding proposals to support the sustainability of Sisanda App Universe beyond the duration of this project at Umhlathuze | G11: 3 Funding Proposals | I11: Month 9 | J11: Month 12
B12: Sub-Total 2 | L12: =SUM(L7:L11) | M12: =SUM(M7:M11) -> 20000 | N12: =SUM(N7:N11) -> 20000 | O12: =SUM(O7:O11) -> 10000 | P12: =SUM(P7:P11) -> 50000
B13: 3. Execution (Deployment) | C13: 3.1. Deployment Readiness | D13: To prepare for deployment of the Sisanda App at all selcted schools | E13: 3.1.1 | F13: Identify and finalize product sites | G13: Finalized list of sites signed off by City of uMhlathuze | H13: PDF | I13: Month 2 | J13: Month 2 | K13: 1 Week | L13: 0 | N13: 0 | O13: 0 | P13: =SUM(L13:O13)
E14: 3.1.2 | F14: Address any potential gaps that might impact project implementation. | G14: Updated Risk Register | H14: Excel Sheet | I14: Month 2 | J14: Month 2 | K14: 2 Week | L14: 0 | N14: 0 | O14: 0 | P14: =SUM(L14:O14) -> 0
E15: 3.1.3 | F15: Procure and deliver of 165 tablets to the selected schools | G15: Invoice and Delivery Notes. | H15: PDF | I15: Month 2 | J15: Month 2 | K15: 1 Week | L15: 506664 | P15: =SUM(L15:O15) -> 506664
E16: 3.1.4 | F16: Purchase school Licences | G16: Proof of payment of licenses | H16: .xsl | I16: Month 2 | J16: Month 2 | K16: 1 Week | L16: 402336 | N16: 0 | O16: 0 | P16: =SUM(L16:O16) -> 402336
E17: 3.1.5 | F17: Install the app on tablets for all participating schools. | G17: Successful installation test report for all devices | H17: .apk | I17: Month 2 | J17: Month 2 | K17: 1 Week | L17: 0 | N17: 0 | O17: 0 | P17: =SUM(L17:O17) -> 0
E18: 3.1.6 | F18: Conduct quality assurance checks to ensure optimal app performance of the app on all devices | G18: Quality Assurance Report | H18: PDF | I18: Month 2 | J18: Month 2 | K18: 1 Week
C19: 3..2 Training | D19: To Equip teachers and IT staff with the skills to use the app effectively. | E19: 3.2..1 | F19: Schdeule training sessions for teachers and IT staff. | G19: Scanned Attendance Register and Training Report | H19: PDF | I19: Month 3 | J19: Month 3 | K19: 1 Month | L19: 5000 | M19: 0 | N19: 0 | O19: 0 | P19: =SUM(L19:O19)
E20: 3.2..2 | F20: Conduct hands-on demonstration sessions. | G20: Scanned Attendance Register and Training Report | H20: Website Page
E21: 3.2..3 | F21: Update and distribute user manuals and FAQs. | G21: Proof of updated manuals and distribution lsists | H21: Printed Manuals
C22: 3.3 Deployment | D22: To successfully roll out the app across the selected designated schools. | E22: 3.3.1 | F22: Distribute tablets to the schools. | G22: Signed delivery notes | H22: PDF | I22: Month 3 | J22: Month 12 | K22: 8 Month | L22: 5000 | M22: 0 | N22: 0 | O22: 0 | P22: =SUM(L22:O22)
E23: 3.3.2 | F23: Provide delivery notes for teachers or school management to sign, confirming delivery.
E24: 3.3.3 | F24: Provide on-site support during the initial days of implementation.
B25: Sub-Total 3 | L25: =L4+L7+L13+L15+L16+L18+L19+L22 | M25: =M4+M7+M13+M15+M16+M18+M19+M22 -> 0 | N25: =N4+N7+N13+N15+N16+N18+N19+N22 -> 0 | O25: =O4+O7+O13+O15+O16+O18+O19+O22 -> 0 | P25: =SUM(L25:O25)
B26: 4. Support, Monitoring and Evaluation | C26: 4.1.Monitoring and Support | D26: To ensure smooth app operation and address any arising issues. | E26: 4.1.1 | F26: Establish a helpline or support portal for schools to report issues or seek assistance. | G26: Support portal | H26: Online Portal | I26: Month 3 | J26: Month 12 | K26: 9 Month | L26: 5000 | M26: 0 | N26: 6000 | O26: 0 | P26: =SUM(L26:O28)
E27: 4.1.2 | F27: Monitor app usage, performance, and gather user feedback. | G27: Monthly monitoring reports | H27: PDF
E28: 4.1.3 | F28: Provide any and all required updates to the Sisanda App. | G28: Update Reports | H28: APK
C29: 4.2. Feedback Collection | D29: To assess user experience and identify areas for improvement. | E29: 4.2.1 | F29: Conduct surveys or focus group discussions with teachers and students. | G29: Feedback reports from users | H29: PDF | I29: Month 3 | J29: Month 12 | K29: 9 Month | L29: 0 | M29: 0 | N29: 0 | O29: 0 | P29: =SUM(L29:O31)
E30: 4.2.2 | F30: Analyze feedback to discern trends, challenges, or suggestions. | G30: Feedback reports from users | H30: PDF
E31: 4.2.3 | F31: Plan enhancements based on the feedback received. | G31: Update Product roadmap | H31: Trello
C32: 4.3.Continuous Improvement | D32: To ensure the app's continued relevance and efficacy. | E32: 4.3.1 | F32: Release updates or patches based on feedback and technological advancements. | G32: Updated app versions | H32: APK | I32: Month 3 | J32: Month 12 | K32: 9 Month | L32: 0 | M32: 5000 | N32: 5000 | O32: 5000 | P32: =SUM(L32:O32)
E33: 4.3.2 | F33: Schedule refresher training sessions on any new features added to the app | G33: Training sessions for new features | H33: PDF and Support page
E34: 4.3.3 | F34: Engage with schools for sustained collaboration and improvement. | G34: Feedback reports | H34: PDF
B35: Sub-Total 4 | L35: =SUM(L26:L34) | M35: =SUM(M26:M34) -> 5000 | N35: =SUM(N26:N34) -> 11000 | O35: =SUM(O26:O34) -> 5000 | P35: =SUM(P26:P34) -> 26000
B36: 5. Closure | C36: 5.1.Project Review and Reporting | D36: Conclude the implementation phase and transition to regular operations. | E36: 5.1.1 | F36: Document the implementation process, challenges encountered, and lessons learned. | G36: Final project close out eport | H36: PDF | I36: Month 10 | J36: Month 12 | K36: 2 Month | L36: 0 | M36: 0 | N36: 0 | O36: 5000 | P36: =SUM(L36:O36)
B37: Sub-Total 5 | L37: =SUM(L36) | M37: =SUM(M36) -> 0 | N37: =SUM(N36) -> 0 | O37: =SUM(O36) -> 5000 | P37: =SUM(P36) -> 5000
B38: Grand Total (Sub-Total 1 +2+3+4+5) | L38: =L6+L12+L25+L35+L37 | M38: =M6+M12+M25+M35+M37 -> 25000 | N38: =N6+N12+N25+N35+N37 -> 31000 | O38: =O6+O12+O25+O35+O37 -> 20000 | P38: =P6+P12+P25+P35+P37 -> 1000000
C40: Disbursement Schedule
C41: Disbursement 1 (30%) | D41: 300000
C42: Disbursement 2 (50%) | D42: =P38*50%
...

Sheet Breakdown expediture
B1: Sisanda.com
B2: INVOICES | H2: LABOUR | I2: OPERATIONAL COST: | K2: CAPITAL EQUIPMENT
A3: nr | B3: Date | C3: Name of Company | D3: Description | E3: Invoice | F3: Link for invoice | G3: Link for POP | H3: Personnel | I3: Overheads/Admin/ Bank Charge | J3: Office material and Rent | K3: Procure and deliver of 165 tablets to the selected schools | L3: Purchase school Licences
A604: TOTAL | E604: =SUM(E1:E603) | H604: =SUM(H1:H603) | I604: =SUM(I1:I603) | J604: =SUM(J1:J603) | K604: =SUM(K1:K603) | L604: =SUM(L1:L603)

Sheet Quarterly financial
A1: DETAILED EXPENSE REPORT - QUARTERLY
A2: Name of Institution:
A3: Current Reporting Period: | E3: Jan - March 2024
A4: Agreement Period:
A5: Agreement No:
A6: Invoice Number:
A7: (Information in the budget section must be aligned with agreed budget according to the project plan and contract. Please ensure the budget is sufficiently detailed and add notes to explain all significant variations from budget.
B8: Budget for Quarter | C8: Actual for Quarter | D8: Variance | E8: % Variance | F8: Reasons for variances | G8: Comments
A9: INCOME | D9: (For all income= Actual for the quarter less budget for the quarter) | E9: (% variance= variance/actual for the quarter) | F9: (All reasons for variances can be detailed on the page below; you can also include any further notes) | G9: For any expenditure over R100k, please provide details in the form of notes linked to the project activity
A10: Balance brought forward from previous quarter (this should be the surplus/ (deficit) from previous quarter) | B10: 0
A11: TIA Funding received/budgeted in the quarter | B11: 924000 | C11: =C16 | D11: =B11-C11 | E11: =D11/B11 | F11: Budget is more than the funds tranfered by TIA | G11: https://drive.google.com/file/d/1qVQtyr7AXdiVotWmxgNo4LdfyX6nrc14/view?usp=sharing
A12: Other Income: | B12: 0 | C12: 0 | D12: =C12-B12 | E12: 0
A13: Interest | B13: 0 | C13: 0 | D13: =C13-B13 -> 0 | E13: 0
A14: VAT refund | B14: 0 | C14: 0 | D14: =C14-B14 -> 0 | E14: 0
A15: etc. | B15: 0 | C15: 0 | D15: =C15-B15 -> 0 | E15: 0
A16: GRAND TOTAL INCOME | B16: =SUM(B10:B11) | C16: =C17 | D16: =B16-C16 | E16: =D16/B16 | F16: Budget is more than the funds tranfered by TIA | G16: https://drive.google.com/file/d/1qVQtyr7AXdiVotWmxgNo4LdfyX6nrc14/view?usp=sharing
A17: EXPENSES (allocated to TIA funding) | B17: =B18+B79+B120+B162 | C17: =C18+C79+C120+C162 | D17: =B17-C17 | E17: (% variance= variance/budget for the quarter) | F17: Budget is more than the funds tranfered by TIA | G17: (For all expenses= Budget for the quarter less actual for the quarter)
A18: PERSONNEL COSTS: | B18: =SUM(B19:B78) | C18: =SUM(C19:C78) | D18: =B18-C18 | E18: =D18/C18
B19: 0 | C19: 0 | D19: =B19-C19 | E19: 0
B20: 0 | C20: 0 | D20: =B20-C20 | E20: 0
B21: 0 | C21: 0 | D21: =B21-C21 | E21: 0
B22: 0 | C22: 0 | D22: =B22-C22 | E22: 0
B23: 0 | C23: 0 | D23: =B23-C23 | E23: 0
B24: 0 | C24: 0 | D24: =B24-C24 | E24: 0
B25: 0 | C25: 0 | D25: =B25-C25 | E25: 0
B26: 0 | C26: 0 | D26: =B26-C26 | E26: 0
B27: 0 | C27: 0 | D27: =B27-C27 | E27: 0
B28: 0 | C28: 0 | D28: =B28-C28 | E28: 0
B29: 0 | C29: 0 | D29: =B29-C29 | E29: 0
B30: 0 | C30: 0 | D30: =B30-C30 | E30: 0
... B78: 0 | C78: 0 | D78: =B78-C78 | E78: 0
A79: OPERATIONAL COST: | B79: =SUM(B80:B119) | C79: =SUM(C80:C119) | D79: =B79-C79 | E79: =D79/C79
B80: 0 | C80: 0 | D80: =B80-C80 | E80: 0
B81: 0 | C81: 0 | D81: =B81-C81 | E81: 0
B82: 0 | C82: 0 | D82: =B82-C82 | E82: 0
B83: 0 | C83: 0 | D83: =B83-C83 | E83: 0
B84: 0 | C84: 0 | D84: =B84-C84 | E84: 0
B85: 0 | C85: 0 | D85: =B85-C85 | E85: 0
B86: 0 | C86: 0 | D86: =B86-C86 | E86: 0
B87: 0 | C87: 0 | D87: =B87-C87 | E87: 0
...

Sheet Next Quarter Projection
A1: Quarter Projection
A2: Name of Institution: | B2: ABC Academy
A3: Current Reporting Period: | B3: Q1
A4: Projection Period: | B4: Q2
A6: INCOME | B6: Budget for Quarter
A7: Balance brought forward from previous quarter (this should be the surplus/ (deficit) from previous quarter) | B7: =SUM('Quarterly financial'!C204:C205)
A8: TIA Funding received/budgeted in the quarter | B8: 25000
A9: Total Budget | B9: =SUM(B7:B8)
A10: PROJECTED EXPENDITURE | B10: =SUM(B11+B22+B29) | C10: Activity Details ( Include details of activitives linked to the budget line item in the approved project plan)
A11: PERSONNEL COSTS: | B11: =SUM(B12:B20)
A12: Develop a stakholder map to identifiy funding sources and potential partners for Umhlatuze | B12: 20000
A13: Develop a business sustainability model for Sisanda App Universe
A14: Source funding proposals to support the sustainability of Sisanda App Universe beyond the duration of this project at Umhlathuze
A15: Schdeule training sessions for teachers and IT staff. | B15: 5000
A16: Conduct hands-on demonstration sessions.
A17: Update and distribute user manuals and FAQs.
A18: Distribute tablets to the schools. | B18: 5000
A19: Provide delivery notes for teachers or school management to sign, confirming delivery.
A20: Provide on-site support during the initial days of implementation.
A22: OPERATIONAL COST: | B22: =SUM(B23:B28)
A23: Establish a helpline or support portal for schools to report issues or seek assistance. | B23: 5000
A24: Monitor app usage, performance, and gather user feedback.
A25: Provide any and all required updates to the Sisanda App.
A26: Release updates or patches based on feedback and technological advancements. | B26: 5000
A27: Schedule refresher training sessions on any new features added to the app
A28: Engage with schools for sustained collaboration and improvement.
A29: CAPITAL EQUIPMENT: | B29: =SUM(B30:B31)
A30: Procure and deliver of 165 tablets to the selected schools | B30: =SUM('Quarterly financial'!D121) | C30: This amount is carried over from the remaining funds in Q1
A31: Purchase school Licences | B31: =SUM('Quarterly financial'!D122) | C31: This amount is carried over from the remaining funds in Q2
A32: Sub-contracting/ consultants | B32: =SUM(B33:B33)
B33: 0
A34: CONSUMABLES: | B34: =SUM(B35:B38)
B35: 0
B36: 0
B37: 0
B38: 0
A40: GRAND TOTAL PROJECTION: : | B40: =B11+B22+B29+B32+B34
A41: SURPLUS / DEFICIT | B41: =B9-B40 | C41: (Provide notes for anticipated surplus or deficit)
A44: Declaration: I hereby declare that the information supplied is a true reflection of the financial records of Project (Insert Project name and number)
A45: Financial information prepared by: Yasmin
...

Sheet Bank and cash reconciliation
A1: BANK AND CASH RECONCILIATION
A2: Name of Institution: ABC Academy
A3: Current Reporting Period: Jan - March 2024
A4: Agreement Period: Q1
A5: Agreement No:
A6: Invoice Number:
B7: R | C7: R
A8: Amount Transferred from TIA | C8: 300000
A9: Less Actual Expenses | C9: ='Quarterly financial'!C203-15499
A10: Surplus (deficit) | C10: =C8-C9
A11: (from above)
A12: Reconciling items:
A13: Bank and cash balance | C13: =C10
A14: (as in bank statement balances for all bank accounts held, physical cash holdings, or as in university or council cost centre statement, where applicable)

Sheet Accumulated financial info
B2: Project Budget to date | C2: Project Actual to date | D2: Variance | E2: % Variance
A4: INCOME | D4: (For all income= Actual year to date less budget year to date) | E4: (% variance= variance/actual year to date)
A5: TIA Funding | B5: ='Quarterly financial'!B11 | C5: =SUM('Quarterly financial'!C11) | D5: =C5-B5 | E5: =D5/B5
A6: Co- funding received : | B6: 0 | C6: 0 | D6: =C6-B6 -> 0
A7: Consortium Partner A | B7: 0 | C7: 0 | D7: =C7-B7 -> 0
A8: Consortium Partner B | B8: 0 | C8: 0 | D8: =C8-B8 -> 0
A9: Consortium Partner C | B9: 0 | C9: 0 | D9: =C9-B9 -> 0
A10: Consortium Partner D | B10: 0 | C10: 0 | D10: =C10-B10 -> 0
A11: Other income: | B11: 0 | C11: 0 | D11: =C11-B11 -> 0
A12: Interest | B12: 0 | C12: 0 | D12: =C12-B12 -> 0
A13: VAT refund | B13: 0 | C13: 0 | D13: =C13-B13 -> 0
A14: etc. | B14: 0 | C14: 0 | D14: =C14-B14 -> 0
A15: Grand Total Income | B15: =SUM(B5:B14) | C15: =SUM('Quarterly financial'!C16) | D15: =C15-B15 -> -640174.61 | E15: =D15/B15
A16: EXPENSES (allocated to TIA funding) | B16: =SUM('Quarterly financial'!B17) | C16: =SUM('Quarterly financial'!C17) | D16: (For all expenses= Budget year to date less actual year to date) | E16: (% variance= variance/budget year to date)
A17: Personnel costs: | B17: ='Quarterly financial'!B18 | C17: ='Quarterly financial'!C18 | D17: =B17-C17 | E17: =D17/C17
A18: (Project related human resources salaries, bonuses etc.) | B18: 0 | C18: 0 | D18: =B18-C18 -> 0 | E18: 0
A19: ='Quarterly financial'!A19 | B19: ='Quarterly financial'!B19 | C19: ='Quarterly financial'!C19 | D19: =B19-C19 -> 0 | E19: 0
A20: ='Quarterly financial'!A20 | B20: ='Quarterly financial'!B20 | C20: ='Quarterly financial'!C20 | D20: 0 | E20: 0
A21: ='Quarterly financial'!A21 | B21: ='Quarterly financial'!B21 | C21: ='Quarterly financial'!C21 | D21: 0 | E21: 0
A22: ='Quarterly financial'!A22 | B22: ='Quarterly financial'!B22 | C22: ='Quarterly financial'!C22 | D22: 0 | E22: 0
A23: ='Quarterly financial'!A23 | B23: ='Quarterly financial'!B23 | C23: ='Quarterly financial'!C23 | D23: 0 | E23: 0
A24: ='Quarterly financial'!A24 | B24: ='Quarterly financial'!B24 | C24: ='Quarterly financial'!C24 | D24: 0 | E24: 0
A25: ='Quarterly financial'!A25 | B25: ='Quarterly financial'!B25 | C25: ='Quarterly financial'!C25 | D25: 0 | E25: 0
A26: ='Quarterly financial'!A26 | B26: ='Quarterly financial'!B26 | C26: ='Quarterly financial'!C26 | D26: 0 | E26: 0
A27: ='Quarterly financial'!A27 | B27: ='Quarterly financial'!B27 | C27: ='Quarterly financial'!C27 | D27: 0 | E27: 0
A28: ='Quarterly financial'!A28 | B28: ='Quarterly financial'!B28 | C28: ='Quarterly financial'!C28 | D28: =B28-C28 | E28: =D28/C28
A29: ='Quarterly financial'!A29 | B29: ='Quarterly financial'!B29 | C29: ='Quarterly financial'!C29 | D29: 0 | E29: 0
A30: ='Quarterly financial'!A30 | B30: ='Quarterly financial'!B30 | C30: ='Quarterly financial'!C30 | D30: =B30-C30 | E30: 0
A31: ='Quarterly financial'!A31 | B31: ='Quarterly financial'!B31 | C31: ='Quarterly financial'!C31 | D31: =B31-C31 | E31: =D31/C31
A32: ='Quarterly financial'!A32 | B32: ='Quarterly financial'!B32 | C32: ='Quarterly financial'!C32 | D32: 0 | E32: 0
A33: ='Quarterly financial'!A33 | B33: ='Quarterly financial'!B33 | C33: ='Quarterly financial'!C33 | D33: 0 | E33: 0
A34: ='Quarterly financial'!A34 | B34: ='Quarterly financial'!B34 | C34: ='Quarterly financial'!C34 | D34: =B34-C34 | E34: =D34/C34
A35: ='Quarterly financial'!A35 | B35: ='Quarterly financial'!B35 | C35: ='Quarterly financial'!C35 | D35: 0 | E35: 0
A36: ='Quarterly financial'!A41 | B36: ='Quarterly financial'!B41 | C36: ='Quarterly financial'!C41 | D36: 0 | E36: 0
A37: Operational costs: | B37: ='Quarterly financial'!B79 | C37: ='Quarterly financial'!C79 | D37: =B37-C37 | E37: =D37/C37
A38: (E.g. equipment maintenance, travel etc.) | B38: 0 | C38: 0 | D38: =B38-C38 -> 0 | E38: 0
A39: Overheads/Admin/ Bank Charge | B39: 0 | C39: =SUM('Quarterly financial'!C80) | D39: =B39-C39 -> -2717.69 | E39: 0
A40: Capital equipment: | B40: ='Quarterly financial'!B120 | C40: ='Quarterly financial'!C120 | D40: =B40-C40 | E40: =D40/B40
A41: (put detailed capital items purchased individually or in groups as applicable) | B41: 0 | C41: 0 | D41: =B41-C41 -> 0 | E41: 0
A42: ='Quarterly financial'!A121 | B42: ='Quarterly financial'!B121 | C42: ='Quarterly financial'!C121 | D42: =B42-C42 -> 339737.13 | E42: =D42/B42 -> 0.67053734
...
